Workbook

Sheet Ringkasan
B2: Laporan Hasil Preprocessing Mengikuti Jurnal: Klasifikasi Kanker Kulit (3 Kelas)
B3: Spark on YARN | Preprocessing: pad & resize, Dull Razor, active contour snake, isolasi lesi | Augmentasi saat training
B5: 1. Informasi umum
B6: Komponen | C6: Keterangan
B7: Tujuan | C7: Mengukur kinerja pipeline preprocessing mengikuti jurnal pada 4 skenario worker × partisi, dan membandingkannya dengan baseline.
B8: Kelas | C8: Nevus, melanoma, seborrheic keratosis.
B9: Dataset | C9: 22.051 citra: train 17.656, validasi 2.192, test 2.203.
B10: Preprocessing | C10: Pad & resize 224×224, Dull Razor, active contour snake, isolasi lesi (fallback citra utuh bila mask tidak wajar).
B11: Augmentasi | C11: Flip, rotasi ±15°, brightness/contrast 0,7–1,3. Hanya pada data train.
B12: Model | C12: ResNet-50 + Triplet Attention (AK85).
B13: Platform | C13: Kaggle. Hadoop 3.3.6, Spark 3.5.5 (YARN), TensorFlow/Keras, GPU Tesla T4.
B14: Skenario | C14: 2W2P, 2W8P, 8W2P, 8W8P (W = jumlah worker, P = jumlah partisi).
B15: Acuan preprocessing | C15: Behara, Bhero & Agee (2024), LA-CapsNet, Diagnostics 14, 636 (sesuai penulisan di notebook).
B16: Tanggal eksekusi | C16: 28 September 2026 (menurut timestamp results.csv).
B18: 2. Hasil utama
B19: Indikator | C19: Nilai | D19: Skenario | E19: Keterangan
B20: Akurasi test tertinggi | C20: =MAX('Hasil Akurasi'!E6:E9) -> 0.6754 | D20: =INDEX('Hasil Akurasi'!B6:B9,MATCH(MAX('Hasil Akurasi'!E6:E9),'Hasil Akurasi'!E6:E9,0)) -> 2W2P | E20: Skenario terbaik pada akurasi.
B21: Akurasi test terendah | C21: =MIN('Hasil Akurasi'!E6:E9) -> 0.6246 | D21: =INDEX('Hasil Akurasi'!B6:B9,MATCH(MIN('Hasil Akurasi'!E6:E9),'Hasil Akurasi'!E6:E9,0)) -> 8W8P | E21: Skenario terendah pada akurasi.
B22: Macro F1 tertinggi | C22: =MAX('Hasil Akurasi'!F6:F9) -> 0.6026 | D22: =INDEX('Hasil Akurasi'!B6:B9,MATCH(MAX('Hasil Akurasi'!F6:F9),'Hasil Akurasi'!F6:F9,0)) -> 2W2P | E22: Rata-rata F1 tiga kelas.
B23: ROC-AUC tertinggi | C23: =MAX('Hasil Akurasi'!G6:G9) -> 0.8424 | D23: =INDEX('Hasil Akurasi'!B6:B9,MATCH(MAX('Hasil Akurasi'!G6:G9),'Hasil Akurasi'!G6:G9,0)) -> 2W2P | E23: Metode one-vs-rest.
B24: Selisih akurasi vs baseline (rata-rata, poin) | C24: ='Perbandingan Baseline'!E19 -> -10.1675 | D24: Semua skenario | E24: Negatif = lebih rendah dari baseline.
B25: Preprocessing tercepat (detik) | C25: =MIN('Hasil Preprocessing'!F6:F9) -> 240.74 | D25: =INDEX('Hasil Preprocessing'!B6:B9,MATCH(MIN('Hasil Preprocessing'!F6:F9),'Hasil Preprocessing'!F6:F9,0)) -> 8W8P | E25: Waktu tahap preprocessing terdistribusi.
B26: Preprocessing terlambat (detik) | C26: =MAX('Hasil Preprocessing'!F6:F9) -> 280.25 | D26: =INDEX('Hasil Preprocessing'!B6:B9,MATCH(MAX('Hasil Preprocessing'!F6:F9),'Hasil Preprocessing'!F6:F9,0)) -> 8W2P | E26: Selisih dengan yang tercepat sekitar 16,4%.
B27: Rasio waktu vs baseline (rata-rata, kali) | C27: ='Perbandingan Baseline'!E11 -> 2.8483886 | D27: Semua skenario | E27: Di atas 1 = lebih lama dari baseline.
B28: Citra fallback segmentasi | C28: ='Hasil Preprocessing'!F17 -> 0.16602422 | D28: Semua skenario | E28: Citra dipakai utuh (tanpa isolasi lesi).
B29: Rata-rata waktu training (detik) | C29: =AVERAGE('Hasil Akurasi'!L6:L9) -> 618.4625 | D29: Semua skenario | E29: Training terpusat, hampir sama di semua skenario.
B31: 3. Temuan utama
B32: No | C32: Temuan
B33: 1 | C33: Akurasi test 62,46–67,54% dan macro F1 0,570–0,603. Skenario 2W2P paling tinggi.
B34: 2 | C34: Hasil lebih rendah dari baseline: akurasi turun 8,2–11,1 poin, macro F1 turun 0,088–0,111.
B35: 3 | C35: Waktu preprocessing 240,74–280,25 detik, sekitar 2,6–3,1 kali lebih lama dari baseline.
B36: 4 | C36: Snake berhasil mengisolasi lesi pada 83,40% citra. Sisanya 16,60% memakai fallback (citra utuh).
B37: 5 | C37: 8W8P paling cepat (240,74 detik) dengan CPU hampir penuh (99,72%). 8W2P paling lambat (280,25 detik).
B38: 6 | C38: Melanoma hanya dikenali 51–57% (baseline 66–71%). Sekitar 29–34% melanoma diprediksi sebagai seborrheic keratosis.
B39: 7 | C39: Val loss masih turun di epoch 10, jadi model belum konvergen dan masih bisa ditingkatkan.

Sheet Pipeline
B2: Alur Kerja (Pipeline) Eksperimen
B3: Arsitektur hybrid: prapemrosesan medis terdistribusi di Spark on YARN, pelatihan terpusat di GPU driver.
B5: Data (CSV + citra) → HDFS → Preprocessing PySpark (pad-resize, Dull Razor, snake, isolasi) → Shard .npz → Driver (NumPy) → Training GPU (augmentasi) → Evaluasi → results.csv
B7: No | C7: Tahap | D7: Kegiatan | E7: Alat / Teknologi | F7: Keluaran
B8: 1 | C8: Setup lingkungan | D8: Deteksi Kaggle. Pasang Java 11, Hadoop 3.3.6, Spark 3.5.5, dan SSH. Atur environment variable. | E8: Bash, Python | F8: Lingkungan siap
B9: 2 | C9: Konfigurasi HDFS | D9: HDFS pseudo-distributed, replikasi 1. Format NameNode, jalankan daemon, buat direktori kerja. | E9: HDFS | F9: Penyimpanan data siap
B10: 3 | C10: Konfigurasi YARN & Spark | D10: Executor 1 core, heap 1.152 MB (+384 MB overhead). NodeManager 14.336 MB dan 10 vcore. Mode client. | E10: YARN, Spark | F10: Klaster siap
B11: 4 | C11: Ingesti data | D11: Baca manifest CSV. Seragamkan label. Resize 384×384 (JPEG q85). Unggah ke HDFS per kelas. | E11: Pandas, PIL, HDFS | F11: 22.051 citra di HDFS
B12: 5 | C12: Audit data | D12: Hitung jumlah file dan ukuran per kelas. Hitung rasio ketimpangan (4,70). | E12: HDFS CLI | F12: Ringkasan kelas
B13: 6 | C13: Alokasi executor | D13: Tunggu sampai jumlah executor aktif sama dengan target. Catat waktu alokasi YARN. | E13: PySpark, YARN | F13: Waktu alokasi tercatat
B14: 7 | C14: Preprocessing terdistribusi | D14: Bagi daftar path ke N partisi. Tiap partisi: pad & resize 224×224, Dull Razor, active contour snake, isolasi lesi (fallback citra utuh bila mask tidak wajar). Simpan uint8. | E14: PySpark RDD, OpenCV, scikit-image | F14: RDD citra terproses
B15: 8 | C15: Sharding | D15: Tiap partisi menulis shard .npz (64 citra per shard) ke HDFS. | E15: PySpark, NumPy | F15: 346–350 shard
B16: 9 | C16: Pemuatan ke driver | D16: Unduh shard. Pisahkan Train, Val, Test sesuai CSV split. | E16: HDFS, NumPy | F16: Array data (±3,09 GB)
B17: 10 | C17: Hentikan Spark | D17: SparkSession dihentikan agar RAM executor dilepas sebelum training. | E17: Spark | F17: RAM tersedia
B18: 11 | C18: Pelatihan terpusat | D18: Latih ResNet-50 + Triplet Attention. 10 epoch, batch 32, class weight seimbang. Augmentasi hanya pada data train. | E18: TensorFlow/Keras, GPU Tesla T4 | F18: Model terbaik (.keras)
B19: 12 | C19: Evaluasi | D19: Hitung akurasi, macro F1, ROC-AUC, classification report, dan confusion matrix pada test set. | E19: scikit-learn | F19: Metrik test set
B20: 13 | C20: Pencatatan hasil | D20: Catat waktu alokasi, waktu preprocessing, CPU, RAM, dan metrik ke results.csv. | E20: CSV | F20: Log tiap skenario
B22: Catatan: grafik komparasi 4 skenario (dari results.csv) hanya ada di notebook 8W8P (4-7).

Sheet Metodologi
B2: Metodologi Penelitian
B3: Preprocessing mengikuti jurnal acuan (LA-CapsNet). Keterangan di bawah diambil dari kode notebook.
B5: 1. Desain eksperimen
B6: Komponen | C6: Keterangan
B7: Pendekatan | C7: Hybrid. Prapemrosesan citra terdistribusi di Spark on YARN. Pelatihan model terpusat di satu GPU pada driver.
B8: Variabel yang diubah | C8: Jumlah worker {2, 8} dan jumlah partisi {2, 8}. Total 4 skenario: 2W2P, 2W8P, 8W2P, 8W8P.
B9: Variabel yang dijaga tetap | C9: Data, split, model, hyperparameter, jumlah epoch, dan ukuran tiap executor.
B10: Yang diukur | C10: Waktu alokasi YARN, waktu preprocessing, throughput, CPU, dan RAM. Serta akurasi, macro F1, ROC-AUC, dan waktu training.
B11: Acuan preprocessing | C11: Behara, Bhero & Agee (2024), LA-CapsNet, Diagnostics 14, 636 (sesuai penulisan di notebook).
B13: 2. Konfigurasi lingkungan
B14: Komponen | C14: Keterangan
B15: Platform | C15: Kaggle Notebook (1 mesin).
B16: CPU / RAM | C16: 4 core fisik, RAM 32.100 MB (±31 GiB).
B17: GPU | C17: Tesla T4 (2 unit terdeteksi, 13.756 MB tiap unit).
B18: Perangkat lunak | C18: OpenJDK 11, Hadoop 3.3.6, Spark 3.5.5.
B19: Mode Spark | C19: YARN, deploy mode client. Driver memory 4 GB. Application Master 512 MB (+384 MB overhead).
B20: HDFS | C20: Pseudo-distributed, replikasi 1.
B21: Executor | C21: 1 core, heap 1.152 MB + overhead 384 MB (kontainer 1.536 MB). Ukuran sama di semua skenario.
B22: YARN NodeManager | C22: 14.336 MB dan 10 vcore. Resource calculator: DominantResource.
B24: 3. Arsitektur model (ResNet-50 + Triplet Attention, AK85)
B25: Komponen | C25: Keterangan
B26: Input | C26: Citra RGB 224×224, rentang [0, 1].
B27: Penyesuaian skala | C27: Kalikan 255, ubah RGB ke BGR, kurangi mean ImageNet (skema caffe).
B28: Backbone | C28: ResNet-50 bobot ImageNet, tanpa top layer, dibekukan (trainable = False).
B29: Triplet Attention | C29: Dipasang pada keluaran conv4_block6_out (14×14×1024). Tiga cabang: C×H, C×W, H×W.
B30: Penggabungan fitur | C30: Average pool (2.048) + max pool (2.048) dari ResNet, ditambah average pool attention (1.024). Total 5.120 dimensi.
B31: Klasifier | C31: BatchNorm → Dense 512 (ReLU, L2 0,001) → Dropout 0,5 → Dense 256 (ReLU, L2 0,001) → Dropout 0,4 → Dense 3 (softmax).
B33: 4. Konfigurasi pelatihan
B34: Komponen | C34: Keterangan
B35: Optimizer | C35: Adam, learning rate 0,0001.
B36: Loss | C36: Categorical crossentropy.
B37: Batch size / epoch | C37: 32 / maksimum 10 epoch (552 langkah per epoch).
B38: Penanganan ketimpangan | C38: Class weight seimbang: melanoma 1,508; nevus 0,521; seborrheic keratosis 2,400.
B39: Augmentasi (train saja) | C39: Flip horizontal dan vertikal acak, rotasi acak −15° sampai +15°, brightness/contrast acak faktor 0,7–1,3. Val dan test tidak diaugmentasi.
B40: Callback | C40: ReduceLROnPlateau (val_loss, faktor 0,5, sabar 2). EarlyStopping (val_loss, sabar 5, kembalikan bobot terbaik). ModelCheckpoint (val_loss).
B41: Pemuatan batch | C41: Generator BatchSequence: iris array per batch, augmentasi (bila train), lalu bagi 255.
B43: 5. Metrik evaluasi
B44: Komponen | C44: Keterangan
B45: Accuracy | C45: Persentase prediksi yang benar.
B46: Macro F1 | C46: Rata-rata F1 ketiga kelas dengan bobot sama. Cocok untuk data tidak seimbang.
...

Sheet Dataset
B2: Dataset yang Digunakan
B3: Manifest master: dataset_irisan_multiclass_final.csv (22.051 citra, 3 kelas).
B5: 1. Distribusi kelas
B6: Kelas | C6: Kode Label | D6: Jumlah Citra | E6: Persentase | F6: Ukuran di HDFS (MB) | G6: Bobot Kelas
B7: nevus | C7: NV | D7: 14148 | E7: =D7/$D$10 -> 0.64160356 | F7: 236.5 | G7: 0.5207
B8: melanoma | C8: MEL | D8: 4895 | E8: =D8/$D$10 -> 0.2219854 | F8: 89.7 | G8: 1.5083
B9: seborrheic_keratosis | C9: BKL | D9: 3008 | E9: =D9/$D$10 -> 0.13641105 | F9: 55.5 | G9: 2.4002
B10: Total | D10: =SUM(D7:D9) -> 22051 | E10: =SUM(E7:E9) -> 1 | F10: =SUM(F7:F9) -> 381.7
B11: Rasio ketimpangan (terbanyak / tersedikit) | E11: =MAX(D7:D9)/MIN(D7:D9) -> 4.7034574
B13: 2. Pembagian data (train / val / test)
B14: Set | C14: nevus (NV) | D14: melanoma (MEL) | E14: seborrheic_keratosis (BKL) | F14: Total | G14: Persentase
B15: Train | C15: 11302 | D15: 3902 | E15: 2452 | F15: =SUM(C15:E15) -> 17656 | G15: =F15/$F$18 -> 0.80068931
B16: Validasi | C16: 1455 | D16: 450 | E16: 287 | F16: =SUM(C16:E16) -> 2192 | G16: =F16/$F$18 -> 0.099405923
B17: Test | C17: 1391 | D17: 543 | E17: 269 | F17: =SUM(C17:E17) -> 2203 | G17: =F17/$F$18 -> 0.099904766
B18: Total | C18: =SUM(C15:C17) -> 14148 | D18: =SUM(D15:D17) -> 4895 | E18: =SUM(E15:E17) -> 3008 | F18: =SUM(F15:F17) -> 22051 | G18: =SUM(G15:G17) -> 1
B19: Cek total dengan tabel 1 | F19: =IF(F18=D10,"Sesuai","Tidak sesuai") -> Sesuai
B21: 3. Catatan data
B22: Aspek | C22: Keterangan
B23: Sumber label | C23: Label medis diseragamkan (harmonisasi) ke tiga kelas: NV, MEL, BKL.
B24: Pemetaan folder | C24: NV → nevus, MEL → melanoma, BKL → seborrheic_keratosis.
B25: Indeks label model | C25: melanoma = 0, nevus = 1, seborrheic_keratosis = 2 (urutan abjad).
B26: Folder dataset di Kaggle | C26: dataset-riset-irisanmelbklnv-1719ham (lokasi file CSV master dan CSV split menurut output notebook).
B27: Pembagian data | C27: Memakai file split resmi (train, val, test) dari CSV. Notebook mencetak keterangan bebas kebocoran, tetapi tidak menjalankan pemeriksaan kebocoran.
B28: Ketimpangan kelas | C28: Nevus 64,2% data, seborrheic keratosis 13,6%. Rasio 4,70. Ditangani dengan class weight seimbang.
B29: Penyimpanan | C29: Citra di-resize 384×384 (JPEG q85) lalu diunggah ke HDFS per folder kelas.

Sheet Preprocessing
B2: Tahapan Preprocessing (Mengikuti Jurnal)
B3: Pad & resize → Dull Razor → active contour snake → isolasi lesi. Parameter diambil dari kode notebook.
B5: 1. Preprocessing terdistribusi (dijalankan di executor Spark)
B6: No | C6: Langkah | D6: Parameter | E6: Dilakukan di | F6: Tujuan
B7: 1 | C7: Baca citra | D7: Citra dibaca dari HDFS (PyArrow), didecode dengan OpenCV, lalu diubah ke RGB. | E7: Executor Spark | F7: Citra siap diproses.
B8: 2 | C8: Pad & resize | D8: Reflection padding sampai persegi (sisi = dimensi terpanjang), lalu resize ke 224×224 (INTER_AREA). | E8: Executor Spark | F8: Menjaga rasio aspek lesi. Sesuai input model.
B9: 3 | C9: Dull Razor | D9: Grayscale, Black-Hat kernel 11×1 dan 1×11 (diambil nilai maksimum), threshold 15, inpainting Telea radius 2. | E9: Executor Spark | F9: Menghapus rambut.
B10: 4 | C10: Persiapan snake | D10: Gaussian blur (sigma 2) pada grayscale. Kurva awal berbentuk elips 60 titik, dicari otomatis dari kontur Otsu terbesar (luas 5–80% citra, paling dekat ke pusat). Bila tidak ada: elips 35% di tengah. | E10: Executor Spark | F10: Titik awal snake per citra.
B11: 5 | C11: Active contour snake | D11: skimage.active_contour dengan alpha 0,015, beta 10,0, gamma 0,001, maksimum 15 iterasi. Hasil diisi jadi mask dan dirapikan (morphology close elips 5×5). | E11: Executor Spark | F11: Batas lesi.
B12: 6 | C12: Kontrol kualitas mask | D12: Mask dipakai bila luasnya 4–75% dari luas citra. Di luar itu, atau bila snake error: fallback ke citra utuh (setelah Dull Razor). | E12: Executor Spark | F12: Mencegah snake collapse atau melebar.
B13: 7 | C13: Isolasi lesi | D13: Mask diterapkan ke citra (bitwise and). Latar dihitamkan, lesi dipertahankan. | E13: Executor Spark | F13: Model hanya melihat area lesi.
B14: 8 | C14: Simpan uint8 | D14: Nilai piksel 0–255, tipe uint8, bentuk 224×224×3. Label dari nama folder: melanoma 0, nevus 1, seborrheic_keratosis 2. | E14: Executor Spark | F14: Hemat memori (±3,09 GB untuk seluruh data).
B16: 2. Saat pelatihan (di generator batch)
B17: No | C17: Langkah | D17: Parameter | E17: Dilakukan di | F17: Tujuan
B18: 1 | C18: Augmentasi (train saja) | D18: Flip horizontal (p 0,5), flip vertikal (p 0,5), rotasi acak −15° sampai +15° (border reflect), brightness/contrast acak faktor 0,7–1,3. | E18: Generator batch | F18: Menambah variasi data train. Val dan test tidak diaugmentasi.
B19: 2 | C19: Normalisasi [0, 1] | D19: Nilai piksel dibagi 255. | E19: Generator batch | F19: Skala input seragam.
B20: 3 | C20: Penyesuaian skala ImageNet | D20: Kali 255, RGB ke BGR, kurangi mean (103,939; 116,779; 123,68). | E20: Di dalam model | F20: Sesuai skema bobot ResNet-50 ImageNet.
B21: 4 | C21: Class weight | D21: Melanoma 1,508; nevus 0,521; seborrheic_keratosis 2,400. | E21: Saat training | F21: Mengurangi bias ke kelas nevus.
B23: 3. Beda dengan jurnal acuan (menurut catatan di kode)
B24: No | C24: Aspek | D24: Keterangan
B25: 1 | C25: Ukuran citra | D25: Jurnal 299×299. Di sini 224×224 agar sesuai input model AK85.
B26: 2 | C26: Normalisasi mean 0 / var 1 | D26: Sengaja tidak dipakai. Model memakai layer ResNetCaffePreprocess yang mengharapkan input [0, 1].
B27: 3 | C27: Random crop dan noise | D27: Tidak diimplementasikan. Berisiko memotong lesi yang sudah diisolasi.
B28: 4 | C28: Inisialisasi snake dan fallback | D28: Cara inisialisasi kurva awal dan batas fallback 4–75% bukan dari jurnal. Ditambahkan agar snake stabil.

Sheet Hasil Preprocessing
B2: Hasil Prapemrosesan Terdistribusi (Spark on YARN)
B3: Pipeline: pad & resize, Dull Razor, active contour snake, isolasi lesi. 22.051 citra diproses di tiap skenario, tidak ada yang gagal.
B5: Skenario | C5: Worker | D5: Partisi | E5: Waktu Alokasi YARN (detik) | F5: Waktu Preprocessing (detik) | G5: Jumlah Citra | H5: Throughput (citra/detik) | I5: Speedup vs 2W2P | J5: CPU Rata-rata (%) | K5: RAM Rata-rata (MB) | L5: Sampel Monitor | M5: Waktu Tulis Shard (detik) | N5: Speedup Shard vs 2W2P | O5: Jumlah Shard | P5: Citra/Partisi Terkecil | Q5: Citra/Partisi Terbesar
B6: 2W2P | C6: 2 | D6: 2 | E6: 0.01 | F6: 264.76 | G6: 22051 | H6: =G6/F6 -> 83.28675 | I6: =$F$6/F6 -> 1 | J6: 63.31 | K6: 6195.38 | L6: 529 | M6: 57.4 | N6: =$M$6/M6 -> 1 | O6: 346 | P6: 11020 | Q6: 11031
B7: 2W8P | C7: 2 | D7: 8 | E7: 0.01 | F7: 263.93 | G7: 22051 | H7: =G7/F7 -> 83.548668 | I7: =$F$6/F7 -> 1.0031448 | J7: 62.87 | K7: 6561.88 | L7: 528 | M7: 53.5 | N7: =$M$6/M7 -> 1.0728972 | O7: 350 | P7: 2740 | Q7: 2760
B8: 8W2P | C8: 8 | D8: 2 | E8: 6.06 | F8: 280.25 | G8: 22051 | H8: =G8/F8 -> 78.683318 | I8: =$F$6/F8 -> 0.94472792 | J8: 63.86 | K8: 8548.25 | L8: 560 | M8: 51 | N8: =$M$6/M8 -> 1.1254902 | O8: 346 | P8: 11016 | Q8: 11035
B9: 8W8P | C9: 8 | D9: 8 | E9: 6.13 | F9: 240.74 | G9: 22051 | H9: =G9/F9 -> 91.596743 | I9: =$F$6/F9 -> 1.0997757 | J9: 99.72 | K9: 9851.83 | L9: 480 | M9: 32.3 | N9: =$M$6/M9 -> 1.7770898 | O9: 349 | P9: 2744 | Q9: 2770
B10: Rata-rata | E10: =AVERAGE(E6:E9) -> 3.0525 | F10: =AVERAGE(F6:F9) -> 262.42 | H10: =AVERAGE(H6:H9) -> 84.27887 | I10: =AVERAGE(I6:I9) -> 1.0119121 | J10: =AVERAGE(J6:J9) -> 72.44 | K10: =AVERAGE(K6:K9) -> 7789.335 | M10: =AVERAGE(M6:M9) -> 48.55
B11: Terkecil | E11: =MIN(E6:E9) -> 0.01 | F11: =MIN(F6:F9) -> 240.74 | H11: =MIN(H6:H9) -> 78.683318 | I11: =MIN(I6:I9) -> 0.94472792 | J11: =MIN(J6:J9) -> 62.87 | K11: =MIN(K6:K9) -> 6195.38 | M11: =MIN(M6:M9) -> 32.3
B12: Terbesar | E12: =MAX(E6:E9) -> 6.13 | F12: =MAX(F6:F9) -> 280.25 | H12: =MAX(H6:H9) -> 91.596743 | I12: =MAX(I6:I9) -> 1.0997757 | J12: =MAX(J6:J9) -> 99.72 | K12: =MAX(K6:K9) -> 9851.83 | M12: =MAX(M6:M9) -> 57.4
B13: Selisih waktu preprocessing (terbesar − terkecil) / terkecil | F13: =(F12-F11)/F11 -> 0.16411897
B15: Hasil segmentasi active contour snake (Terisolasi = citra dengan lesi terisolasi; Fallback = citra dipakai utuh)
B16: Skenario | C16: Terisolasi | D16: Fallback | E16: Total | F16: % Fallback | G16: Cek vs Jumlah Citra
B17: 2W2P | C17: 18390 | D17: 3661 | E17: =C17+D17 -> 22051 | F17: =D17/E17 -> 0.16602422 | G17: =IF(E17=G6,"Sesuai","Tidak sesuai") -> Sesuai
B18: 2W8P | C18: 18390 | D18: 3661 | E18: =C18+D18 -> 22051 | F18: =D18/E18 -> 0.16602422 | G18: =IF(E18=G7,"Sesuai","Tidak sesuai") -> Sesuai
B19: 8W2P | C19: 18390 | D19: 3661 | E19: =C19+D19 -> 22051 | F19: =D19/E19 -> 0.16602422 | G19: =IF(E19=G8,"Sesuai","Tidak sesuai") -> Sesuai
B20: 8W8P | C20: 18390 | D20: 3661 | E20: =C20+D20 -> 22051 | F20: =D20/E20 -> 0.16602422 | G20: =IF(E20=G9,"Sesuai","Tidak sesuai") -> Sesuai
B22: Catatan
B23: 1. W = jumlah worker (executor), P = jumlah partisi. Speedup = waktu 2W2P dibagi waktu skenario tersebut. Nilai di bawah 1 berarti lebih lambat dari 2W2P.
B24: 2. Waktu diukur mulai dari membaca citra di HDFS sampai seluruh RDD selesai diproses (materialisasi RDD). Waktu tulis shard diukur terpisah.
B25: 3. Waktu alokasi YARN adalah lama menunggu semua executor aktif, dicatat di results.csv (stage yarn_container_allocation).
B26: 4. CPU dan RAM diukur untuk seluruh sistem (sampling tiap 0,5 detik), bukan hanya executor.
B27: 5. Mesin hanya punya 4 core fisik. Pada skenario 8 worker, 8 executor berbagi 4 core.
B28: 6. Jumlah citra fallback sama di keempat skenario (3.661). Hasil segmentasi konsisten antarskenario.
B29: 7. Fallback: citra dipakai utuh bila luas mask snake di luar 4–75% dari luas citra, atau snake gagal.

Sheet Hasil Akurasi
B2: Hasil Evaluasi Model pada Test Set
B3: Test set: 2.203 citra. Angka tebal menandai nilai terbaik pada kolomnya.
B5: Skenario | C5: Worker | D5: Partisi | E5: Akurasi Test | F5: Macro F1 | G5: ROC-AUC (OvR) | H5: Loss Test | I5: Akurasi Train (Epoch 10) | J5: Akurasi Val (Epoch 10) | K5: Selisih Train−Val | L5: Waktu Training (detik) | M5: Waktu Training (menit) | N5: Epoch
B6: 2W2P | C6: 2 | D6: 2 | E6: 0.6754 | F6: 0.6026 | G6: 0.8424 | H6: 1.6159 | I6: =SUMIFS('Log Training'!$D$6:$D$45,'Log Training'!$B$6:$B$45,$B6,'Log Training'!$C$6:$C$45,10) -> 0.6437 | J6: =SUMIFS('Log Training'!$F$6:$F$45,'Log Training'!$B$6:$B$45,$B6,'Log Training'!$C$6:$C$45,10) -> 0.6743 | K6: =I6-J6 -> -0.0306 | L6: 618.16 | M6: =L6/60 -> 10.302667 | N6: 10
B7: 2W8P | C7: 2 | D7: 8 | E7: 0.65 | F7: 0.5823 | G7: 0.8362 | H7: 1.6219 | I7: =SUMIFS('Log Training'!$D$6:$D$45,'Log Training'!$B$6:$B$45,$B7,'Log Training'!$C$6:$C$45,10) -> 0.6384 | J7: =SUMIFS('Log Training'!$F$6:$F$45,'Log Training'!$B$6:$B$45,$B7,'Log Training'!$C$6:$C$45,10) -> 0.646 | K7: =I7-J7 -> -0.0076 | L7: 615.77 | M7: =L7/60 -> 10.262833 | N7: 10
B8: 8W2P | C8: 8 | D8: 2 | E8: 0.6378 | F8: 0.5723 | G8: 0.8318 | H8: 1.634 | I8: =SUMIFS('Log Training'!$D$6:$D$45,'Log Training'!$B$6:$B$45,$B8,'Log Training'!$C$6:$C$45,10) -> 0.6448 | J8: =SUMIFS('Log Training'!$F$6:$F$45,'Log Training'!$B$6:$B$45,$B8,'Log Training'!$C$6:$C$45,10) -> 0.6505 | K8: =I8-J8 -> -0.0057 | L8: 619.81 | M8: =L8/60 -> 10.330167 | N8: 10
B9: 8W8P | C9: 8 | D9: 8 | E9: 0.6246 | F9: 0.5703 | G9: 0.8331 | H9: 1.6663 | I9: =SUMIFS('Log Training'!$D$6:$D$45,'Log Training'!$B$6:$B$45,$B9,'Log Training'!$C$6:$C$45,10) -> 0.6402 | J9: =SUMIFS('Log Training'!$F$6:$F$45,'Log Training'!$B$6:$B$45,$B9,'Log Training'!$C$6:$C$45,10) -> 0.6168 | K9: =I9-J9 -> 0.0234 | L9: 620.11 | M9: =L9/60 -> 10.335167 | N9: 10
B10: Rata-rata | E10: =AVERAGE(E6:E9) -> 0.64695 | F10: =AVERAGE(F6:F9) -> 0.581875 | G10: =AVERAGE(G6:G9) -> 0.835875 | H10: =AVERAGE(H6:H9) -> 1.634525 | I10: =AVERAGE(I6:I9) -> 0.641775 | J10: =AVERAGE(J6:J9) -> 0.6469 | K10: =AVERAGE(K6:K9) -> -0.005125 | L10: =AVERAGE(L6:L9) -> 618.4625 | M10: =AVERAGE(M6:M9) -> 10.307708
B11: Tertinggi | E11: =MAX(E6:E9) -> 0.6754 | F11: =MAX(F6:F9) -> 0.6026 | G11: =MAX(G6:G9) -> 0.8424 | H11: =MAX(H6:H9) -> 1.6663 | I11: =MAX(I6:I9) -> 0.6448 | J11: =MAX(J6:J9) -> 0.6743 | K11: =MAX(K6:K9) -> 0.0234 | L11: =MAX(L6:L9) -> 620.11 | M11: =MAX(M6:M9) -> 10.335167
B12: Terendah | E12: =MIN(E6:E9) -> 0.6246 | F12: =MIN(F6:F9) -> 0.5703 | G12: =MIN(G6:G9) -> 0.8318 | H12: =MIN(H6:H9) -> 1.6159 | I12: =MIN(I6:I9) -> 0.6384 | J12: =MIN(J6:J9) -> 0.6168 | K12: =MIN(K6:K9) -> -0.0306 | L12: =MIN(L6:L9) -> 615.77 | M12: =MIN(M6:M9) -> 10.262833
B13: Rentang | E13: =MAX(E6:E9)-MIN(E6:E9) -> 0.0508 | F13: =MAX(F6:F9)-MIN(F6:F9) -> 0.0323 | G13: =MAX(G6:G9)-MIN(G6:G9) -> 0.0106 | H13: =MAX(H6:H9)-MIN(H6:H9) -> 0.0504 | I13: =MAX(I6:I9)-MIN(I6:I9) -> 0.0064 | J13: =MAX(J6:J9)-MIN(J6:J9) -> 0.0575 | K13: =MAX(K6:K9)-MIN(K6:K9) -> 0.054 | L13: =MAX(L6:L9)-MIN(L6:L9) -> 4.34 | M13: =MAX(M6:M9)-MIN(M6:M9) -> 0.072333333
B15: Catatan
B16: 1. Setiap skenario dilatih satu kali. Selisih antarskenario belum bisa disimpulkan sebagai perbedaan nyata.
B17: 2. Data, model, dan pengaturan pelatihan sama di semua skenario. Yang berbeda hanya jumlah worker dan partisi saat preprocessing.
B18: 3. Semua skenario berjalan 10 epoch penuh. EarlyStopping tidak aktif karena val_loss masih turun sampai epoch 10.
B19: 4. Akurasi train (epoch 10) dihitung pada data yang diaugmentasi, sedangkan akurasi val pada data asli. Nilai keduanya tidak setara secara langsung.
B20: 5. Loss test mencakup penalti L2 dan bobot kelas, sehingga nilainya lebih besar dari crossentropy biasa.

Sheet Per Kelas
B2: Hasil Evaluasi per Kelas
B3: Sumber: classification report pada test set (2.203 citra).
B5: Skenario | C5: Kelas | D5: Precision | E5: Recall | F5: F1-score | G5: Support
B6: 2W2P | C6: melanoma | D6: 0.6 | E6: 0.53 | F6: 0.56 | G6: 543
B7: 2W2P | C7: nevus | D7: 0.87 | E7: 0.73 | F7: 0.79 | G7: 1391
B8: 2W2P | C8: seborrheic_keratosis | D8: 0.33 | E8: 0.7 | F8: 0.45 | G8: 269
B9: 2W8P | C9: melanoma | D9: 0.58 | E9: 0.51 | F9: 0.54 | G9: 543
B10: 2W8P | C10: nevus | D10: 0.9 | E10: 0.69 | F10: 0.78 | G10: 1391
B11: 2W8P | C11: seborrheic_keratosis | D11: 0.3 | E11: 0.73 | F11: 0.43 | G11: 269
B12: 8W2P | C12: melanoma | D12: 0.55 | E12: 0.52 | F12: 0.53 | G12: 543
B13: 8W2P | C13: nevus | D13: 0.87 | E13: 0.67 | F13: 0.76 | G13: 1391
B14: 8W2P | C14: seborrheic_keratosis | D14: 0.31 | E14: 0.7 | F14: 0.42 | G14: 269
B15: 8W8P | C15: melanoma | D15: 0.52 | E15: 0.57 | F15: 0.55 | G15: 543
B16: 8W8P | C16: nevus | D16: 0.91 | E16: 0.63 | F16: 0.74 | G16: 1391
B17: 8W8P | C17: seborrheic_keratosis | D17: 0.3 | E17: 0.73 | F17: 0.42 | G17: 269
B19: Rata-rata per kelas (4 skenario)
C20: Kelas | D20: Precision | E20: Recall | F20: F1-score | G20: Support
B21: Rata-rata | C21: melanoma | D21: =AVERAGEIFS(D$6:D$17,$C$6:$C$17,$C21) -> 0.5625 | E21: =AVERAGEIFS(E$6:E$17,$C$6:$C$17,$C21) -> 0.5325 | F21: =AVERAGEIFS(F$6:F$17,$C$6:$C$17,$C21) -> 0.545 | G21: =AVERAGEIFS(G$6:G$17,$C$6:$C$17,$C21) -> 543
B22: Rata-rata | C22: nevus | D22: =AVERAGEIFS(D$6:D$17,$C$6:$C$17,$C22) -> 0.8875 | E22: =AVERAGEIFS(E$6:E$17,$C$6:$C$17,$C22) -> 0.68 | F22: =AVERAGEIFS(F$6:F$17,$C$6:$C$17,$C22) -> 0.7675 | G22: =AVERAGEIFS(G$6:G$17,$C$6:$C$17,$C22) -> 1391
B23: Rata-rata | C23: seborrheic_keratosis | D23: =AVERAGEIFS(D$6:D$17,$C$6:$C$17,$C23) -> 0.31 | E23: =AVERAGEIFS(E$6:E$17,$C$6:$C$17,$C23) -> 0.715 | F23: =AVERAGEIFS(F$6:F$17,$C$6:$C$17,$C23) -> 0.43 | G23: =AVERAGEIFS(G$6:G$17,$C$6:$C$17,$C23) -> 269
B25: Angka tebal = kelas dengan F1 tertinggi.

Sheet Confusion Matrix
B2: Confusion Matrix Ternormalisasi (Persentase per Baris)
B3: Baris = label asli, kolom = hasil prediksi. Nilai diagonal adalah prediksi yang benar (recall).
B5: Skenario 2W2P
B6: Label asli \ Prediksi | C6: melanoma | D6: nevus | E6: seborrheic_keratosis | F6: Total baris
B7: melanoma | C7: 0.5267 | D7: 0.1878 | E7: 0.2855 | F7: =SUM(C7:E7) -> 1
B8: nevus | C8: 0.1114 | D8: 0.7283 | E8: 0.1603 | F8: =SUM(C8:E8) -> 1
B9: seborrheic_keratosis | C9: 0.1301 | D9: 0.1673 | E9: 0.7026 | F9: =SUM(C9:E9) -> 1
B12: Skenario 2W8P
B13: Label asli \ Prediksi | C13: melanoma | D13: nevus | E13: seborrheic_keratosis | F13: Total baris
B14: melanoma | C14: 0.512 | D14: 0.1455 | E14: 0.3425 | F14: =SUM(C14:E14) -> 1
B15: nevus | C15: 0.1186 | D15: 0.6887 | E15: 0.1927 | F15: =SUM(C15:E15) -> 1
B16: seborrheic_keratosis | C16: 0.1487 | D16: 0.1227 | E16: 0.7286 | F16: =SUM(C16:E16) -> 1
B19: Skenario 8W2P
B20: Label asli \ Prediksi | C20: melanoma | D20: nevus | E20: seborrheic_keratosis | F20: Total baris
B21: melanoma | C21: 0.5212 | D21: 0.1786 | E21: 0.3002 | F21: =SUM(C21:E21) -> 1
B22: nevus | C22: 0.1395 | D22: 0.6722 | E22: 0.1884 | F22: =SUM(C22:E22) -> 1.0001
B23: seborrheic_keratosis | C23: 0.1524 | D23: 0.1524 | E23: 0.6952 | F23: =SUM(C23:E23) -> 1
B26: Skenario 8W8P
B27: Label asli \ Prediksi | C27: melanoma | D27: nevus | E27: seborrheic_keratosis | F27: Total baris
B28: melanoma | C28: 0.5691 | D28: 0.1087 | E28: 0.3223 | F28: =SUM(C28:E28) -> 1.0001
B29: nevus | C29: 0.1661 | D29: 0.6262 | E29: 0.2078 | F29: =SUM(C29:E29) -> 1.0001
B30: seborrheic_keratosis | C30: 0.1822 | D30: 0.0892 | E30: 0.7286 | F30: =SUM(C30:E30) -> 1
B33: Ringkasan: arah kesalahan citra melanoma
B34: Skenario | C34: Melanoma benar dikenali | D34: Melanoma diprediksi nevus | E34: Melanoma diprediksi SK | F34: Total
B35: 2W2P | C35: =C7 -> 0.5267 | D35: =D7 -> 0.1878 | E35: =E7 -> 0.2855 | F35: =SUM(C35:E35) -> 1
B36: 2W8P | C36: =C14 -> 0.512 | D36: =D14 -> 0.1455 | E36: =E14 -> 0.3425 | F36: =SUM(C36:E36) -> 1
B37: 8W2P | C37: =C21 -> 0.5212 | D37: =D21 -> 0.1786 | E37: =E21 -> 0.3002 | F37: =SUM(C37:E37) -> 1
B38: 8W8P | C38: =C28 -> 0.5691 | D38: =D28 -> 0.1087 | E38: =E28 -> 0.3223 | F38: =SUM(C38:E38) -> 1.0001
B40: Catatan: persentase dibaca dari gambar heatmap notebook (dibulatkan 2 desimal), sehingga total baris bisa 100,01%. Diagonal dicetak tebal. SK = seborrheic keratosis.

Sheet Log Training
B2: Log Pelatihan per Epoch
B3: Sumber: keluaran model.fit tiap notebook. Akurasi dan loss train dihitung pada data yang sudah diaugmentasi.
B5: Skenario | C5: Epoch | D5: Akurasi Train | E5: Loss Train | F5: Akurasi Val | G5: Loss Val | H5: Learning Rate
B6: 2W2P | C6: 1 | D6: 0.526 | E6: 2.5228 | F6: 0.6099 | G6: 2.0732 | H6: 0.0001
B7: 2W2P | C7: 2 | D7: 0.5726 | E7: 2.2618 | F7: 0.5958 | G7: 2.0694 | H7: 0.0001
B8: 2W2P | C8: 3 | D8: 0.5881 | E8: 2.1435 | F8: 0.656 | G8: 1.9641 | H8: 0.0001
B9: 2W2P | C9: 4 | D9: 0.6072 | E9: 2.056 | F9: 0.6318 | G9: 1.9632 | H9: 0.0001
B10: 2W2P | C10: 5 | D10: 0.6158 | E10: 1.9932 | F10: 0.6373 | G10: 1.9131 | H10: 0.0001
B11: 2W2P | C11: 6 | D11: 0.6196 | E11: 1.9316 | F11: 0.6451 | G11: 1.8659 | H11: 0.0001
B12: 2W2P | C12: 7 | D12: 0.634 | E12: 1.8667 | F12: 0.6597 | G12: 1.7959 | H12: 0.0001
B13: 2W2P | C13: 8 | D13: 0.6297 | E13: 1.8173 | F13: 0.6651 | G13: 1.7495 | H13: 0.0001
B14: 2W2P | C14: 9 | D14: 0.6376 | E14: 1.756 | F14: 0.6505 | G14: 1.7244 | H14: 0.0001
B15: 2W2P | C15: 10 | D15: 0.6437 | E15: 1.696 | F15: 0.6743 | G15: 1.6346 | H15: 0.0001
B16: 2W8P | C16: 1 | D16: 0.5263 | E16: 2.4752 | F16: 0.5575 | G16: 2.163 | H16: 0.0001
B17: 2W8P | C17: 2 | D17: 0.5717 | E17: 2.2392 | F17: 0.6172 | G17: 2.0303 | H17: 0.0001
... B45: 8W8P | C45: 10 | D45: 0.6402 | E45: 1.7047 | F45: 0.6168 | G45: 1.6903 | H45: 0.0001

Sheet Perbandingan Baseline
B2: Perbandingan dengan Baseline
B3: Baseline = notebook 4-4 (resize dan normalisasi saja, tanpa segmentasi dan augmentasi). Model, data, dan split sama.
B5: 1. Kinerja preprocessing terdistribusi
B6: Skenario | C6: Waktu Baseline (detik) | D6: Waktu Jurnal (detik) | E6: Rasio Waktu (kali) | F6: CPU Baseline (%) | G6: CPU Jurnal (%) | H6: RAM Baseline (MB) | I6: RAM Jurnal (MB)
B7: 2W2P | C7: 94.41 | D7: ='Hasil Preprocessing'!F6 -> 264.76 | E7: =D7/C7 -> 2.8043639 | F7: 54 | G7: ='Hasil Preprocessing'!J6 -> 63.31 | H7: 6460.64 | I7: ='Hasil Preprocessing'!K6 -> 6195.38
B8: 2W8P | C8: 89.44 | D8: ='Hasil Preprocessing'!F7 -> 263.93 | E8: =D8/C8 -> 2.9509168 | F8: 58.26 | G8: ='Hasil Preprocessing'!J7 -> 62.87 | H8: 6366.35 | I8: ='Hasil Preprocessing'!K7 -> 6561.88
B9: 8W2P | C9: 91.87 | D9: ='Hasil Preprocessing'!F8 -> 280.25 | E9: =D9/C9 -> 3.0505061 | F9: 61.21 | G9: ='Hasil Preprocessing'!J8 -> 63.86 | H9: 8396.57 | I9: ='Hasil Preprocessing'!K8 -> 8548.25
B10: 8W8P | C10: 93.03 | D10: ='Hasil Preprocessing'!F9 -> 240.74 | E10: =D10/C10 -> 2.5877674 | F10: 91.96 | G10: ='Hasil Preprocessing'!J9 -> 99.72 | H10: 9615.14 | I10: ='Hasil Preprocessing'!K9 -> 9851.83
B11: Rata-rata | C11: =AVERAGE(C7:C10) -> 92.1875 | D11: =AVERAGE(D7:D10) -> 262.42 | E11: =AVERAGE(E7:E10) -> 2.8483886 | F11: =AVERAGE(F7:F10) -> 66.3575 | G11: =AVERAGE(G7:G10) -> 72.44 | H11: =AVERAGE(H7:H10) -> 7709.675 | I11: =AVERAGE(I7:I10) -> 7789.335
B13: 2. Kinerja model pada test set
B14: Skenario | C14: Akurasi Baseline | D14: Akurasi Jurnal | E14: Selisih Akurasi (poin) | F14: Macro F1 Baseline | G14: Macro F1 Jurnal | H14: Selisih Macro F1 | I14: ROC-AUC Baseline | J14: ROC-AUC Jurnal | K14: Selisih ROC-AUC
B15: 2W2P | C15: 0.7571 | D15: ='Hasil Akurasi'!E6 -> 0.6754 | E15: =(D15-C15)*100 -> -8.17 | F15: 0.6903 | G15: ='Hasil Akurasi'!F6 -> 0.6026 | H15: =G15-F15 -> -0.0877 | I15: 0.8938 | J15: ='Hasil Akurasi'!G6 -> 0.8424 | K15: =J15-I15 -> -0.0514
B16: 2W8P | C16: 0.7612 | D16: ='Hasil Akurasi'!E7 -> 0.65 | E16: =(D16-C16)*100 -> -11.12 | F16: 0.6929 | G16: ='Hasil Akurasi'!F7 -> 0.5823 | H16: =G16-F16 -> -0.1106 | I16: 0.895 | J16: ='Hasil Akurasi'!G7 -> 0.8362 | K16: =J16-I16 -> -0.0588
B17: 8W2P | C17: 0.744 | D17: ='Hasil Akurasi'!E8 -> 0.6378 | E17: =(D17-C17)*100 -> -10.62 | F17: 0.6788 | G17: ='Hasil Akurasi'!F8 -> 0.5723 | H17: =G17-F17 -> -0.1065 | I17: 0.892 | J17: ='Hasil Akurasi'!G8 -> 0.8318 | K17: =J17-I17 -> -0.0602
B18: 8W8P | C18: 0.7322 | D18: ='Hasil Akurasi'!E9 -> 0.6246 | E18: =(D18-C18)*100 -> -10.76 | F18: 0.6763 | G18: ='Hasil Akurasi'!F9 -> 0.5703 | H18: =G18-F18 -> -0.106 | I18: 0.8891 | J18: ='Hasil Akurasi'!G9 -> 0.8331 | K18: =J18-I18 -> -0.056
B19: Rata-rata | C19: =AVERAGE(C15:C18) -> 0.748625 | D19: =AVERAGE(D15:D18) -> 0.64695 | E19: =AVERAGE(E15:E18) -> -10.1675 | F19: =AVERAGE(F15:F18) -> 0.684575 | G19: =AVERAGE(G15:G18) -> 0.581875 | H19: =AVERAGE(H15:H18) -> -0.1027 | I19: =AVERAGE(I15:I18) -> 0.892475 | J19: =AVERAGE(J15:J18) -> 0.835875 | K19: =AVERAGE(K15:K18) -> -0.0566
B21: 3. Kelas kunci (test set)
B22: Skenario | C22: Recall Melanoma Baseline | D22: Recall Melanoma Jurnal | E22: F1 Melanoma Baseline | F22: F1 Melanoma Jurnal | G22: Precision SK Baseline | H22: Precision SK Jurnal | I22: F1 SK Baseline | J22: F1 SK Jurnal
B23: 2W2P | C23: 0.68 | D23: =SUMIFS('Per Kelas'!$E$6:$E$17,'Per Kelas'!$B$6:$B$17,$B23,'Per Kelas'!$C$6:$C$17,"melanoma") -> 0.53 | E23: 0.65 | F23: =SUMIFS('Per Kelas'!$F$6:$F$17,'Per Kelas'!$B$6:$B$17,$B23,'Per Kelas'!$C$6:$C$17,"melanoma") -> 0.56 | G23: 0.49 | H23: =SUMIFS('Per Kelas'!$D$6:$D$17,'Per Kelas'!$B$6:$B$17,$B23,'Per Kelas'!$C$6:$C$17,"seborrheic_keratosis") -> 0.33 | I23: 0.57 | J23: =SUMIFS('Per Kelas'!$F$6:$F$17,'Per Kelas'!$B$6:$B$17,$B23,'Per Kelas'!$C$6:$C$17,"seborrheic_keratosis") -> 0.45
B24: 2W8P | C24: 0.66 | D24: =SUMIFS('Per Kelas'!$E$6:$E$17,'Per Kelas'!$B$6:$B$17,$B24,'Per Kelas'!$C$6:$C$17,"melanoma") -> 0.51 | E24: 0.65 | F24: =SUMIFS('Per Kelas'!$F$6:$F$17,'Per Kelas'!$B$6:$B$17,$B24,'Per Kelas'!$C$6:$C$17,"melanoma") -> 0.54 | G24: 0.5 | H24: =SUMIFS('Per Kelas'!$D$6:$D$17,'Per Kelas'!$B$6:$B$17,$B24,'Per Kelas'!$C$6:$C$17,"seborrheic_keratosis") -> 0.3 | I24: 0.58 | J24: =SUMIFS('Per Kelas'!$F$6:$F$17,'Per Kelas'!$B$6:$B$17,$B24,'Per Kelas'!$C$6:$C$17,"seborrheic_keratosis") -> 0.43
B25: 8W2P | C25: 0.69 | D25: =SUMIFS('Per Kelas'!$E$6:$E$17,'Per Kelas'!$B$6:$B$17,$B25,'Per Kelas'!$C$6:$C$17,"melanoma") -> 0.52 | E25: 0.65 | F25: =SUMIFS('Per Kelas'!$F$6:$F$17,'Per Kelas'!$B$6:$B$17,$B25,'Per Kelas'!$C$6:$C$17,"melanoma") -> 0.53 | G25: 0.47 | H25: =SUMIFS('Per Kelas'!$D$6:$D$17,'Per Kelas'!$B$6:$B$17,$B25,'Per Kelas'!$C$6:$C$17,"seborrheic_keratosis") -> 0.31 | I25: 0.55 | J25: =SUMIFS('Per Kelas'!$F$6:$F$17,'Per Kelas'!$B$6:$B$17,$B25,'Per Kelas'!$C$6:$C$17,"seborrheic_keratosis") -> 0.42
B26: 8W8P | C26: 0.71 | D26: =SUMIFS('Per Kelas'!$E$6:$E$17,'Per Kelas'!$B$6:$B$17,$B26,'Per Kelas'!$C$6:$C$17,"melanoma") -> 0.57 | E26: 0.63 | F26: =SUMIFS('Per Kelas'!$F$6:$F$17,'Per Kelas'!$B$6:$B$17,$B26,'Per Kelas'!$C$6:$C$17,"melanoma") -> 0.55 | G26: 0.5 | H26: =SUMIFS('Per Kelas'!$D$6:$D$17,'Per Kelas'!$B$6:$B$17,$B26,'Per Kelas'!$C$6:$C$17,"seborrheic_keratosis") -> 0.3 | I26: 0.58 | J26: =SUMIFS('Per Kelas'!$F$6:$F$17,'Per Kelas'!$B$6:$B$17,$B26,'Per Kelas'!$C$6:$C$17,"seborrheic_keratosis") -> 0.42
B27: Rata-rata | C27: =AVERAGE(C23:C26) -> 0.685 | D27: =AVERAGE(D23:D26) -> 0.5325 | E27: =AVERAGE(E23:E26) -> 0.645 | F27: =AVERAGE(F23:F26) -> 0.545 | G27: =AVERAGE(G23:G26) -> 0.49 | H27: =AVERAGE(H23:H26) -> 0.31 | I27: =AVERAGE(I23:I26) -> 0.57 | J27: =AVERAGE(J23:J26) -> 0.43
B29: 4. Loss pada epoch 10
B30: Skenario | C30: Loss Train Baseline | D30: Loss Train Jurnal | E30: Loss Val Baseline | F30: Loss Val Jurnal
B31: 2W2P | C31: 1.4174 | D31: =SUMIFS('Log Training'!$E$6:$E$45,'Log Training'!$B$6:$B$45,$B31,'Log Training'!$C$6:$C$45,10) -> 1.696 | E31: 1.5162 | F31: =SUMIFS('Log Training'!$G$6:$G$45,'Log Training'!$B$6:$B$45,$B31,'Log Training'!$C$6:$C$45,10) -> 1.6346
B32: 2W8P | C32: 1.3891 | D32: =SUMIFS('Log Training'!$E$6:$E$45,'Log Training'!$B$6:$B$45,$B32,'Log Training'!$C$6:$C$45,10) -> 1.6704 | E32: 1.4864 | F32: =SUMIFS('Log Training'!$G$6:$G$45,'Log Training'!$B$6:$B$45,$B32,'Log Training'!$C$6:$C$45,10) -> 1.6333
B33: 8W2P | C33: 1.4088 | D33: =SUMIFS('Log Training'!$E$6:$E$45,'Log Training'!$B$6:$B$45,$B33,'Log Training'!$C$6:$C$45,10) -> 1.6722 | E33: 1.538 | F33: =SUMIFS('Log Training'!$G$6:$G$45,'Log Training'!$B$6:$B$45,$B33,'Log Training'!$C$6:$C$45,10) -> 1.6506
B34: 8W8P | C34: 1.3924 | D34: =SUMIFS('Log Training'!$E$6:$E$45,'Log Training'!$B$6:$B$45,$B34,'Log Training'!$C$6:$C$45,10) -> 1.7047 | E34: 1.5299 | F34: =SUMIFS('Log Training'!$G$6:$G$45,'Log Training'!$B$6:$B$45,$B34,'Log Training'!$C$6:$C$45,10) -> 1.6903
B35: Rata-rata | C35: =AVERAGE(C31:C34) -> 1.401925 | D35: =AVERAGE(D31:D34) -> 1.685825 | E35: =AVERAGE(E31:E34) -> 1.517625 | F35: =AVERAGE(F31:F34) -> 1.6522
B37: Catatan
B38: 1. Nilai baseline diambil dari laporan baseline sebelumnya (notebook 4-4). Nilai jurnal diambil dari sheet lain di file ini.
B39: 2. Selisih akurasi dalam poin persentase. Selisih negatif berarti hasil jurnal lebih rendah dari baseline.
B40: 3. Rasio waktu di atas 1 berarti preprocessing jurnal lebih lama dari baseline.
B41: 4. SK = seborrheic keratosis. Loss train jurnal dihitung pada data yang diaugmentasi.
B42: 5. Perbedaan preprocessing dan augmentasi diubah bersamaan, sehingga pengaruh tiap komponen belum bisa dipisahkan.

Sheet Grafik
B2: Grafik Hasil Pelatihan
B3: Data grafik diambil otomatis dari sheet Log Training, Hasil Akurasi, dan Perbandingan Baseline.
B4: Akurasi validasi per epoch
B5: Epoch | C5: 2W2P | D5: 2W8P | E5: 8W2P | F5: 8W8P
B6: 1 | C6: =SUMIFS('Log Training'!$F$6:$F$45,'Log Training'!$B$6:$B$45,C$5,'Log Training'!$C$6:$C$45,$B6) -> 0.6099 | D6: =SUMIFS('Log Training'!$F$6:$F$45,'Log Training'!$B$6:$B$45,D$5,'Log Training'!$C$6:$C$45,$B6) -> 0.5575 | E6: =SUMIFS('Log Training'!$F$6:$F$45,'Log Training'!$B$6:$B$45,E$5,'Log Training'!$C$6:$C$45,$B6) -> 0.6223 | F6: =SUMIFS('Log Training'!$F$6:$F$45,'Log Training'!$B$6:$B$45,F$5,'Log Training'!$C$6:$C$45,$B6) -> 0.6437
B7: 2 | C7: =SUMIFS('Log Training'!$F$6:$F$45,'Log Training'!$B$6:$B$45,C$5,'Log Training'!$C$6:$C$45,$B7) -> 0.5958 | D7: =SUMIFS('Log Training'!$F$6:$F$45,'Log Training'!$B$6:$B$45,D$5,'Log Training'!$C$6:$C$45,$B7) -> 0.6172 | E7: =SUMIFS('Log Training'!$F$6:$F$45,'Log Training'!$B$6:$B$45,E$5,'Log Training'!$C$6:$C$45,$B7) -> 0.615 | F7: =SUMIFS('Log Training'!$F$6:$F$45,'Log Training'!$B$6:$B$45,F$5,'Log Training'!$C$6:$C$45,$B7) -> 0.609
B8: 3 | C8: =SUMIFS('Log Training'!$F$6:$F$45,'Log Training'!$B$6:$B$45,C$5,'Log Training'!$C$6:$C$45,$B8) -> 0.656 | D8: =SUMIFS('Log Training'!$F$6:$F$45,'Log Training'!$B$6:$B$45,D$5,'Log Training'!$C$6:$C$45,$B8) -> 0.6072 | E8: =SUMIFS('Log Training'!$F$6:$F$45,'Log Training'!$B$6:$B$45,E$5,'Log Training'!$C$6:$C$45,$B8) -> 0.6396 | F8: =SUMIFS('Log Training'!$F$6:$F$45,'Log Training'!$B$6:$B$45,F$5,'Log Training'!$C$6:$C$45,$B8) -> 0.635
B9: 4 | C9: =SUMIFS('Log Training'!$F$6:$F$45,'Log Training'!$B$6:$B$45,C$5,'Log Training'!$C$6:$C$45,$B9) -> 0.6318 | D9: =SUMIFS('Log Training'!$F$6:$F$45,'Log Training'!$B$6:$B$45,D$5,'Log Training'!$C$6:$C$45,$B9) -> 0.6045 | E9: =SUMIFS('Log Training'!$F$6:$F$45,'Log Training'!$B$6:$B$45,E$5,'Log Training'!$C$6:$C$45,$B9) -> 0.6515 | F9: =SUMIFS('Log Training'!$F$6:$F$45,'Log Training'!$B$6:$B$45,F$5,'Log Training'!$C$6:$C$45,$B9) -> 0.6036
B10: 5 | C10: =SUMIFS('Log Training'!$F$6:$F$45,'Log Training'!$B$6:$B$45,C$5,'Log Training'!$C$6:$C$45,$B10) -> 0.6373 | D10: =SUMIFS('Log Training'!$F$6:$F$45,'Log Training'!$B$6:$B$45,D$5,'Log Training'!$C$6:$C$45,$B10) -> 0.6277 | E10: =SUMIFS('Log Training'!$F$6:$F$45,'Log Training'!$B$6:$B$45,E$5,'Log Training'!$C$6:$C$45,$B10) -> 0.6556 | F10: =SUMIFS('Log Training'!$F$6:$F$45,'Log Training'!$B$6:$B$45,F$5,'Log Training'!$C$6:$C$45,$B10) -> 0.6227
B11: 6 | C11: =SUMIFS('Log Training'!$F$6:$F$45,'Log Training'!$B$6:$B$45,C$5,'Log Training'!$C$6:$C$45,$B11) -> 0.6451 | D11: =SUMIFS('Log Training'!$F$6:$F$45,'Log Training'!$B$6:$B$45,D$5,'Log Training'!$C$6:$C$45,$B11) -> 0.6382 | E11: =SUMIFS('Log Training'!$F$6:$F$45,'Log Training'!$B$6:$B$45,E$5,'Log Training'!$C$6:$C$45,$B11) -> 0.6592 | F11: =SUMIFS('Log Training'!$F$6:$F$45,'Log Training'!$B$6:$B$45,F$5,'Log Training'!$C$6:$C$45,$B11) -> 0.6259
B12: 7 | C12: =SUMIFS('Log Training'!$F$6:$F$45,'Log Training'!$B$6:$B$45,C$5,'Log Training'!$C$6:$C$45,$B12) -> 0.6597 | D12: =SUMIFS('Log Training'!$F$6:$F$45,'Log Training'!$B$6:$B$45,D$5,'Log Training'!$C$6:$C$45,$B12) -> 0.6255 | E12: =SUMIFS('Log Training'!$F$6:$F$45,'Log Training'!$B$6:$B$45,E$5,'Log Training'!$C$6:$C$45,$B12) -> 0.63 | F12: =SUMIFS('Log Training'!$F$6:$F$45,'Log Training'!$B$6:$B$45,F$5,'Log Training'!$C$6:$C$45,$B12) -> 0.6332
B13: 8 | C13: =SUMIFS('Log Training'!$F$6:$F$45,'Log Training'!$B$6:$B$45,C$5,'Log Training'!$C$6:$C$45,$B13) -> 0.6651 | D13: =SUMIFS('Log Training'!$F$6:$F$45,'Log Training'!$B$6:$B$45,D$5,'Log Training'!$C$6:$C$45,$B13) -> 0.6168 | E13: =SUMIFS('Log Training'!$F$6:$F$45,'Log Training'!$B$6:$B$45,E$5,'Log Training'!$C$6:$C$45,$B13) -> 0.6359 | F13: =SUMIFS('Log Training'!$F$6:$F$45,'Log Training'!$B$6:$B$45,F$5,'Log Training'!$C$6:$C$45,$B13) -> 0.6195
B14: 9 | C14: =SUMIFS('Log Training'!$F$6:$F$45,'Log Training'!$B$6:$B$45,C$5,'Log Training'!$C$6:$C$45,$B14) -> 0.6505 | D14: =SUMIFS('Log Training'!$F$6:$F$45,'Log Training'!$B$6:$B$45,D$5,'Log Training'!$C$6:$C$45,$B14) -> 0.6227 | E14: =SUMIFS('Log Training'!$F$6:$F$45,'Log Training'!$B$6:$B$45,E$5,'Log Training'!$C$6:$C$45,$B14) -> 0.6469 | F14: =SUMIFS('Log Training'!$F$6:$F$45,'Log Training'!$B$6:$B$45,F$5,'Log Training'!$C$6:$C$45,$B14) -> 0.6227
B15: 10 | C15: =SUMIFS('Log Training'!$F$6:$F$45,'Log Training'!$B$6:$B$45,C$5,'Log Training'!$C$6:$C$45,$B15) -> 0.6743 | D15: =SUMIFS('Log Training'!$F$6:$F$45,'Log Training'!$B$6:$B$45,D$5,'Log Training'!$C$6:$C$45,$B15) -> 0.646 | E15: =SUMIFS('Log Training'!$F$6:$F$45,'Log Training'!$B$6:$B$45,E$5,'Log Training'!$C$6:$C$45,$B15) -> 0.6505 | F15: =SUMIFS('Log Training'!$F$6:$F$45,'Log Training'!$B$6:$B$45,F$5,'Log Training'!$C$6:$C$45,$B15) -> 0.6168
B18: Loss validasi per epoch
B19: Epoch | C19: 2W2P | D19: 2W8P | E19: 8W2P | F19: 8W8P
B20: 1 | C20: =SUMIFS('Log Training'!$G$6:$G$45,'Log Training'!$B$6:$B$45,C$19,'Log Training'!$C$6:$C$45,$B20) -> 2.0732 | D20: =SUMIFS('Log Training'!$G$6:$G$45,'Log Training'!$B$6:$B$45,D$19,'Log Training'!$C$6:$C$45,$B20) -> 2.163 | E20: =SUMIFS('Log Training'!$G$6:$G$45,'Log Training'!$B$6:$B$45,E$19,'Log Training'!$C$6:$C$45,$B20) -> 2.0817 | F20: =SUMIFS('Log Training'!$G$6:$G$45,'Log Training'!$B$6:$B$45,F$19,'Log Training'!$C$6:$C$45,$B20) -> 2.0275
B21: 2 | C21: =SUMIFS('Log Training'!$G$6:$G$45,'Log Training'!$B$6:$B$45,C$19,'Log Training'!$C$6:$C$45,$B21) -> 2.0694 | D21: =SUMIFS('Log Training'!$G$6:$G$45,'Log Training'!$B$6:$B$45,D$19,'Log Training'!$C$6:$C$45,$B21) -> 2.0303 | E21: =SUMIFS('Log Training'!$G$6:$G$45,'Log Training'!$B$6:$B$45,E$19,'Log Training'!$C$6:$C$45,$B21) -> 2.0393 | F21: =SUMIFS('Log Training'!$G$6:$G$45,'Log Training'!$B$6:$B$45,F$19,'Log Training'!$C$6:$C$45,$B21) -> 2.0515
B22: 3 | C22: =SUMIFS('Log Training'!$G$6:$G$45,'Log Training'!$B$6:$B$45,C$19,'Log Training'!$C$6:$C$45,$B22) -> 1.9641 | D22: =SUMIFS('Log Training'!$G$6:$G$45,'Log Training'!$B$6:$B$45,D$19,'Log Training'!$C$6:$C$45,$B22) -> 1.9886 | E22: =SUMIFS('Log Training'!$G$6:$G$45,'Log Training'!$B$6:$B$45,E$19,'Log Training'!$C$6:$C$45,$B22) -> 1.9863 | F22: =SUMIFS('Log Training'!$G$6:$G$45,'Log Training'!$B$6:$B$45,F$19,'Log Training'!$C$6:$C$45,$B22) -> 1.989
B23: 4 | C23: =SUMIFS('Log Training'!$G$6:$G$45,'Log Training'!$B$6:$B$45,C$19,'Log Training'!$C$6:$C$45,$B23) -> 1.9632 | D23: =SUMIFS('Log Training'!$G$6:$G$45,'Log Training'!$B$6:$B$45,D$19,'Log Training'!$C$6:$C$45,$B23) -> 1.9739 | E23: =SUMIFS('Log Training'!$G$6:$G$45,'Log Training'!$B$6:$B$45,E$19,'Log Training'!$C$6:$C$45,$B23) -> 1.9398 | F23: =SUMIFS('Log Training'!$G$6:$G$45,'Log Training'!$B$6:$B$45,F$19,'Log Training'!$C$6:$C$45,$B23) -> 1.9876
B24: 5 | C24: =SUMIFS('Log Training'!$G$6:$G$45,'Log Training'!$B$6:$B$45,C$19,'Log Training'!$C$6:$C$45,$B24) -> 1.9131 | D24: =SUMIFS('Log Training'!$G$6:$G$45,'Log Training'!$B$6:$B$45,D$19,'Log Training'!$C$6:$C$45,$B24) -> 1.8978 | E24: =SUMIFS('Log Training'!$G$6:$G$45,'Log Training'!$B$6:$B$45,E$19,'Log Training'!$C$6:$C$45,$B24) -> 1.8867 | F24: =SUMIFS('Log Training'!$G$6:$G$45,'Log Training'!$B$6:$B$45,F$19,'Log Training'!$C$6:$C$45,$B24) -> 1.9366
B25: 6 | C25: =SUMIFS('Log Training'!$G$6:$G$45,'Log Training'!$B$6:$B$45,C$19,'Log Training'!$C$6:$C$45,$B25) -> 1.8659 | D25: =SUMIFS('Log Training'!$G$6:$G$45,'Log Training'!$B$6:$B$45,D$19,'Log Training'!$C$6:$C$45,$B25) -> 1.8554 | E25: =SUMIFS('Log Training'!$G$6:$G$45,'Log Training'!$B$6:$B$45,E$19,'Log Training'!$C$6:$C$45,$B25) -> 1.8579 | F25: =SUMIFS('Log Training'!$G$6:$G$45,'Log Training'!$B$6:$B$45,F$19,'Log Training'!$C$6:$C$45,$B25) -> 1.8802
B26: 7 | C26: =SUMIFS('Log Training'!$G$6:$G$45,'Log Training'!$B$6:$B$45,C$19,'Log Training'!$C$6:$C$45,$B26) -> 1.7959 | D26: =SUMIFS('Log Training'!$G$6:$G$45,'Log Training'!$B$6:$B$45,D$19,'Log Training'!$C$6:$C$45,$B26) -> 1.8219 | E26: =SUMIFS('Log Training'!$G$6:$G$45,'Log Training'!$B$6:$B$45,E$19,'Log Training'!$C$6:$C$45,$B26) -> 1.807 | F26: =SUMIFS('Log Training'!$G$6:$G$45,'Log Training'!$B$6:$B$45,F$19,'Log Training'!$C$6:$C$45,$B26) -> 1.8242
B27: 8 | C27: =SUMIFS('Log Training'!$G$6:$G$45,'Log Training'!$B$6:$B$45,C$19,'Log Training'!$C$6:$C$45,$B27) -> 1.7495 | D27: =SUMIFS('Log Training'!$G$6:$G$45,'Log Training'!$B$6:$B$45,D$19,'Log Training'!$C$6:$C$45,$B27) -> 1.7819 | E27: =SUMIFS('Log Training'!$G$6:$G$45,'Log Training'!$B$6:$B$45,E$19,'Log Training'!$C$6:$C$45,$B27) -> 1.7541 | F27: =SUMIFS('Log Training'!$G$6:$G$45,'Log Training'!$B$6:$B$45,F$19,'Log Training'!$C$6:$C$45,$B27) -> 1.7837
B28: 9 | C28: =SUMIFS('Log Training'!$G$6:$G$45,'Log Training'!$B$6:$B$45,C$19,'Log Training'!$C$6:$C$45,$B28) -> 1.7244 | D28: =SUMIFS('Log Training'!$G$6:$G$45,'Log Training'!$B$6:$B$45,D$19,'Log Training'!$C$6:$C$45,$B28) -> 1.7155 | E28: =SUMIFS('Log Training'!$G$6:$G$45,'Log Training'!$B$6:$B$45,E$19,'Log Training'!$C$6:$C$45,$B28) -> 1.6835 | F28: =SUMIFS('Log Training'!$G$6:$G$45,'Log Training'!$B$6:$B$45,F$19,'Log Training'!$C$6:$C$45,$B28) -> 1.7346
B29: 10 | C29: =SUMIFS('Log Training'!$G$6:$G$45,'Log Training'!$B$6:$B$45,C$19,'Log Training'!$C$6:$C$45,$B29) -> 1.6346 | D29: =SUMIFS('Log Training'!$G$6:$G$45,'Log Training'!$B$6:$B$45,D$19,'Log Training'!$C$6:$C$45,$B29) -> 1.6333 | E29: =SUMIFS('Log Training'!$G$6:$G$45,'Log Training'!$B$6:$B$45,E$19,'Log Training'!$C$6:$C$45,$B29) -> 1.6506 | F29: =SUMIFS('Log Training'!$G$6:$G$45,'Log Training'!$B$6:$B$45,F$19,'Log Training'!$C$6:$C$45,$B29) -> 1.6903
B32: Akurasi dan macro F1 pada test set
B33: Skenario | C33: Akurasi Test | D33: Macro F1
B34: ='Hasil Akurasi'!B6 -> 2W2P | C34: ='Hasil Akurasi'!E6 -> 0.6754 | D34: ='Hasil Akurasi'!F6 -> 0.6026
B35: ='Hasil Akurasi'!B7 -> 2W8P | C35: ='Hasil Akurasi'!E7 -> 0.65 | D35: ='Hasil Akurasi'!F7 -> 0.5823
B36: ='Hasil Akurasi'!B8 -> 8W2P | C36: ='Hasil Akurasi'!E8 -> 0.6378 | D36: ='Hasil Akurasi'!F8 -> 0.5723
B37: ='Hasil Akurasi'!B9 -> 8W8P | C37: ='Hasil Akurasi'!E9 -> 0.6246 | D37: ='Hasil Akurasi'!F9 -> 0.5703
B39: Waktu preprocessing: baseline vs jurnal (detik)
B40: Skenario | C40: Baseline | D40: Jurnal
B41: ='Perbandingan Baseline'!B7 -> 2W2P | C41: ='Perbandingan Baseline'!C7 -> 94.41 | D41: ='Perbandingan Baseline'!D7 -> 264.76
B42: ='Perbandingan Baseline'!B8 -> 2W8P | C42: ='Perbandingan Baseline'!C8 -> 89.44 | D42: ='Perbandingan Baseline'!D8 -> 263.93
B43: ='Perbandingan Baseline'!B9 -> 8W2P | C43: ='Perbandingan Baseline'!C9 -> 91.87 | D43: ='Perbandingan Baseline'!D9 -> 280.25
B44: ='Perbandingan Baseline'!B10 -> 8W8P | C44: ='Perbandingan Baseline'!C10 -> 93.03 | D44: ='Perbandingan Baseline'!D10 -> 240.74

Sheet Analisis
B2: Analisis, Keterbatasan, dan Saran
B3: Kalimat bertanda "dugaan" belum diuji langsung pada eksperimen ini.
B5: 1. Temuan utama
B6: No | C6: Aspek | D6: Temuan | E6: Penjelasan
B7: 1 | C7: Kinerja klasifikasi | D7: Akurasi test 62,46–67,54%. Macro F1 0,570–0,603. ROC-AUC 0,832–0,842. Terbaik: 2W2P. | E7: Kemampuan membedakan kelas (ROC-AUC) cukup baik, tetapi akurasi dan F1 masih rendah.
B8: 2 | C8: Dibanding baseline | D8: Akurasi turun 8,2–11,1 poin. Macro F1 turun 0,088–0,111. Turun di keempat skenario. | E8: Preprocessing jurnal ini belum meningkatkan hasil pada konfigurasi yang dipakai.
B9: 3 | C9: Waktu preprocessing | D9: 240,74–280,25 detik, sekitar 2,6–3,1 kali lebih lama dari baseline (89–94 detik). | E9: Dugaan: tambahan Dull Razor dan snake membuat proses lebih berat. Waktu per tahap tidak diukur.
B10: 4 | C10: Pengaruh worker dan partisi | D10: 8W8P tercepat (240,74 detik, speedup 1,10×). 8W2P paling lambat (280,25 detik). 2W8P hampir sama dengan 2W2P. | E10: Pola belum tegas. Tiap skenario dijalankan sekali.
B11: 5 | C11: Penggunaan CPU dan RAM | D11: CPU 8W8P 99,72%, skenario lain sekitar 63%. RAM 6,1–6,4 GB (2 worker) dan 8,3–9,6 GB (8 worker). | E11: CPU hampir penuh pada 8W8P. Dugaan: 8 executor berebut 4 core.
B12: 6 | C12: Waktu alokasi YARN | D12: 0,01 detik untuk 2 worker. 6,06–6,13 detik untuk 8 worker. | E12: Alokasi 8 executor butuh waktu lebih lama, tetapi kecil dibanding waktu preprocessing.
B13: 7 | C13: Hasil segmentasi | D13: 18.390 citra (83,40%) terisolasi kontur. 3.661 citra (16,60%) memakai fallback (citra utuh). | E13: Angka sama di keempat skenario, jadi hasil segmentasi konsisten. Kualitas mask belum diperiksa secara visual.
B14: 8 | C14: Kesulitan per kelas | D14: F1 nevus 0,74–0,79. Melanoma 0,53–0,56. Seborrheic keratosis (SK) 0,42–0,45. | E14: SK punya precision rendah (0,30–0,33) tetapi recall tinggi (0,70–0,73). Model sering memprediksi SK. Dugaan: terkait bobot kelas SK yang besar (2,40).
B15: 9 | C15: Risiko pada melanoma | D15: Recall melanoma 0,51–0,57 (baseline 0,66–0,71). Sekitar 29–34% melanoma diprediksi sebagai SK. | E15: Melanoma paling berbahaya jika terlewat. Ini perlu jadi fokus perbaikan.
B16: 10 | C16: Konvergensi | D16: Val loss masih turun sampai epoch 10. EarlyStopping tidak aktif. Learning rate tetap 0,0001. | E16: Loss train epoch 10 (1,67–1,70) lebih tinggi dari baseline (1,39–1,42). Model belum konvergen. Dugaan: augmentasi memperlambat konvergensi.
B17: 11 | C17: Waktu training | D17: 615,77–620,11 detik di semua skenario. | E17: Sama dengan baseline (623–630 detik). Augmentasi tidak membuat training lebih lama.
B18: 12 | C18: Selisih antarskenario | D18: Akurasi turun berurutan: 2W2P, 2W8P, 8W2P, 8W8P (selisih 5,08 poin). | E18: Jumlah hasil segmentasi identik antarskenario (fallback 3.661), jadi selisih ini kemungkinan variasi acak training (dugaan), bukan efek jumlah worker.
B20: 2. Catatan pada notebook
B21: No | C21: Aspek | D21: Keterangan
B22: 1 | C22: Sel visualisasi preprocessing | D22: Sel visualisasi (Fase 5) masih memakai segmentasi lama (Otsu kanal L*, multi-komponen), bukan snake. Gambarnya tidak menunjukkan hasil snake yang dipakai pipeline.
B23: 2 | C23: Teks kesimpulan | D23: Kesimpulan di akhir notebook sama dengan versi baseline dan belum diperbarui. Teksnya tidak sejalan dengan hasil (akurasi turun).
B24: 3 | C24: Kemiripan dengan jurnal | D24: Pipeline tidak identik dengan jurnal: ukuran 224 (bukan 299), tanpa normalisasi mean 0 / var 1, tanpa random crop dan noise.
B25: 4 | C25: Pemeriksaan kebocoran | D25: Notebook mencetak keterangan bebas kebocoran, tetapi tidak ada kode yang memeriksanya.
B27: 3. Keterbatasan
B28: No | C28: Aspek | D28: Keterangan
B29: 1 | C29: Jumlah percobaan | D29: Tiap skenario dijalankan sekali. Belum ada uji pengulangan atau uji signifikansi.
B30: 2 | C30: Pengaruh tiap komponen | D30: Segmentasi, Dull Razor, dan augmentasi diubah bersamaan. Pengaruh masing-masing belum bisa dipisahkan.
B31: 3 | C31: Sumber daya | D31: Hanya 4 core fisik untuk 8 executor. Hasil speedup dibatasi rebutan CPU.
B32: 4 | C32: Lingkungan | D32: Semua komponen berjalan di satu mesin (pseudo-distributed), bukan klaster multi-node.
B33: 5 | C33: Pengukuran | D33: CPU dan RAM diukur untuk seluruh sistem, bukan per executor. Waktu tidak diukur per tahap preprocessing.
B34: 6 | C34: Training | D34: Pelatihan tidak terdistribusi, jadi waktu training tidak menunjukkan efek jumlah worker.
B36: 4. Saran tindak lanjut
B37: No | C37: Aspek | D37: Keterangan
B38: 1 | C38: Uji tiap komponen | D38: Jalankan terpisah: segmentasi saja, augmentasi saja, lalu gabungan. Bandingkan dengan baseline.
B39: 2 | C39: Periksa hasil snake | D39: Buat visualisasi memakai fungsi snake yang sebenarnya. Periksa 16,60% citra fallback dan kualitas mask.
B40: 3 | C40: Tambah epoch | D40: Val loss masih turun di epoch 10. Naikkan epoch atau atur learning rate, lalu bandingkan.
B41: 4 | C41: Fokus pada melanoma | D41: Cari cara menaikkan recall melanoma (misalnya atur bobot kelas atau threshold).
B42: 5 | C42: Ulangi percobaan | D42: Jalankan tiap skenario minimal 3 kali. Laporkan rata-rata dan simpangan baku.
B43: 6 | C43: Ukur waktu per tahap | D43: Catat waktu Dull Razor dan snake terpisah untuk mengetahui sumber tambahan waktu.
